Workbook
Name _1334: '[5]Development CF'!$D$111
Name _1386: '[5]Development CF'!$D$115
Name _3__123Graph_ACHART_1: '[7]Cash Flow'!$E$20:$X$20
Name _311: '[5]Development CF'!$D$30
Name _324: '[5]Development CF'!$D$31
Name _6__123Graph_BCHART_1: '[7]Cash Flow'!$E$27:$X$27
Name _apr11: '[9]Expire Sched Data'!$F$58:$F$68
Name _ASP1: '[10]E'!$B$5:$P$98
Name _ASP2: '[10]F'!$B$4:$Q$104
Name _aug11: '[9]Expire Sched Data'!$F$92:$F$95
Name _dec10: '[9]Expire Sched Data'!$F$28:$F$32
Name _feb11: '[9]Expire Sched Data'!$F$38:$F$46
Name _i15: '[11]Assmptns'!$C$30
Name _jan11: '[9]Expire Sched Data'!$F$33:$F$37
Name _Jan13: '[9]Expire Sched Data'!$F$104
Name _jul11: '[9]Expire Sched Data'!$F$87:$F$91
Name _jun11: '[9]Expire Sched Data'!$F$79:$F$86
Name _mar11: '[9]Expire Sched Data'!$F$47:$F$57
Name _may11: '[9]Expire Sched Data'!$F$69:$F$78
Name _nov10: '[9]Expire Sched Data'!$F$23:$F$27
Name _NRA15: '[11]Assmptns'!$C$12
Name _oct10: '[9]Expire Sched Data'!$F$14:$F$22
Name _sep11: '[9]Expire Sched Data'!$F$96:$F$103
Name AAA: '[12]Sheet1'!$A$1
Name ACQFEE: '[13]Returns'!$E$64
Name ANALY_START: '[15]Assumptions'!$B$25
Name Apartments: '[18]GENERAL INPUT'!$AF$8
Name apr11rent: '[9]Expire Sched Data'!$L$58:$L$68
Name apr11sf: '[9]Expire Sched Data'!$C$58:$C$68
Name Area_List: '[20]Project Information'!$J$6:$J$13
Name ASSUMPTS: '[10]F'!$I$10:$J$96
Name aug11rent: '[9]Expire Sched Data'!$L$92:$L$95
Name aug11sf: '[9]Expire Sched Data'!$C$92:$C$95
Name BBB: '[12]Sheet1'!$A$1
Name Beds: '[18]GENERAL INPUT'!$G$253
Name BG_0: '[26]BG_Pkg'!$E$539
Name BG_GSF: '[26]BG_Pkg'!$I$6
Name BG_Perimeter_LF: '[26]BG_Pkg'!$E$551
Name BGStall: '[26]BG_Pkg'!$I$7
Name Booger2: '[27]Assumptions'!$A$6:$K$161,'[27]Assumptions'!$A$178:$K$187
Name BTAX: '[20]Project Information'!$E$12
Name BuysOrSells: '[28]Controls'!$C$16:$C$17
Name cap_both: '[31]Sensitivity'!$B$44
Name CapitalExp: '[18]GENERAL INPUT'!$U$212
Name CapLength: '[12]Sheet1'!$C$11
Name Case: '[32]Assumptions'!$A$54
Name CC: '[13]Returns'!$J$46
Name CDV_Ret_Post: '[33]Assumptions'!$I$19
Name CDV_Ret_Pre: '[33]Assumptions'!$I$15
Name ced: $C$16:$MIN$34
Name CMFeeI: '[18]GENERAL INPUT'!$S$88
Name CMFeeII: '[18]GENERAL INPUT'!$S$90
Name Comm_1: '[26]Commercial'!$E$640
Name Comm_GSF: '[26]Commercial'!$I$7
Name Comm_Lobby: '[26]Commercial'!$H$640
Name Commercial: '[18]GENERAL INPUT'!$AI$11
Name CommercialExpUp: '[18]GENERAL INPUT'!$M$273
Name CommercialRentsUp: '[18]GENERAL INPUT'!$M$274
Name CommercialVacancy: '[18]GENERAL INPUT'!$V$205
Name Condos: '[18]GENERAL INPUT'!$AF$9

Sheet Cash Flow
C3: =UPPER("General") -> GENERAL | G3: =UPPER(+D4&" Property Cash Flow") -> DISTRICT NORTH PROPERTY CASH FLOW | Y3: Going-In Cap Rate
C4: Project Name | H4: 1 | I4: =+H4+1 -> 2 | J4: =+I4+1 -> 3 | K4: =+J4+1 -> 4 | L4: =+K4+1 -> 5 | M4: =+L4+1 -> 6 | N4: =+M4+1 -> 7 | O4: =+N4+1 -> 8 | P4: =+O4+1 -> 9 | ... V4: =+U4+1 -> 15 | Y4: =H13/SUM(D12:D13) -> -0.0077855617
C5: Analysis Start | D5: 46266 | G5: =+D5 -> 46266 | H5: =EDATE($D$5,12)-1 -> 46630 | I5: =EDATE(H5,12) -> 46996 | J5: =EDATE(I5,12) -> 47361 | K5: =EDATE(J5,12) -> 47726 | L5: =EDATE(K5,12) -> 48091 | M5: =EDATE(L5,12) -> 48457 | N5: =EDATE(M5,12) -> 48822 | O5: =EDATE(N5,12) -> 49187 | P5: =EDATE(O5,12) -> 49552 | ... V5: =EDATE(U5,12) -> 51744
C6: Year Built / Reno | Y6: Residual Yield
C7: Site Area | G7: Avg. Occupancy | H7: =+H168 -> 0.5 | I7: =+I168 -> 1 | J7: =+J168 -> 1 | K7: =+K168 -> 1 | L7: =+L168 -> 1 | M7: =+M168 -> 1 | N7: =+N168 -> 1 | O7: =+O168 -> 0.833333 | ... V7: =+V168 -> 1 | Y7: =HLOOKUP(D34+1,H4:V27,24) -> 0.094463261
C8: RSF [1]
C9: Occupancy | D9: ='Rent Roll'!F25 -> 1 | G9: Wgtd Avg In-Place Rent | H9: =+H172 -> 18.5 | I9: =+I172 -> 18.87 | J9: =+J172 -> 19.6248 | K9: =+K172 -> 20.4098 | L9: =+L172 -> 21.2262 | M9: =+M172 -> 22.0752 | N9: =+N172 -> 22.9582 | O9: =+O172 -> 23.5008 | ... V9: =+V172 -> 28.7894
G10: Wgtd Avg Market Rent | H10: =+H170 -> 18.5 | I10: =+I170 -> 18.5 | J10: =+J170 -> 19.06 | K10: =+K170 -> 19.63 | L10: =+L170 -> 20.22 | M10: =+M170 -> 20.82 | N10: =+N170 -> 21.45 | O10: =+O170 -> 22.09 | ... V10: =+V170 -> 27.17
C11: =UPPER("Investment Assumptions") -> INVESTMENT ASSUMPTIONS | G11: Variance | H11: =H9/H10-1 -> 0 | I11: =I9/I10-1 -> 0.02 | J11: =J9/J10-1 -> 0.029632739 | K11: =K9/K10-1 -> 0.039724911 | L11: =L9/L10-1 -> 0.049762611 | M11: =M9/M10-1 -> 0.060288184 | N11: =N9/N10-1 -> 0.070312354 | O11: =O9/O10-1 -> 0.063866003 | ... V11: =V9/V10-1 -> 0.059602503
C12: Purchase Price | E12: =+D12/$D$8 -> 188.90795
C13: Closing Costs | D13: =D12*2% -> 240000 | E13: =+D13/$D$8 -> 3.7781591 | G13: Net Operating Income | H13: =+H155 -> -95295.275 | I13: =+I155 -> 1155492.2 | J13: =+J155 -> 1201773.4 | K13: =+K155 -> 1249907.7 | L13: =+L155 -> 1299969.2 | M13: =+M155 -> 1352035.2 | N13: =+N155 -> 1406185.8 | O13: =+O155 -> 1175381.7 | ... V13: =+V155 -> 587809.17
C14: 0.015 | D14: =+D59 -> 120239.73 | E14: =+D14/$D$8 -> 1.8928534
C15: 0.01 | D15: =+C15*$D$12 -> 120000 | E15: =+D15/$D$8 -> 1.8890795 | G15: Tenant Improvements | H15: =-H157 -> -327143.45 | I15: =-I157 -> 0 | J15: =-J157 -> 0 | K15: =-K157 -> 0 | L15: =-L157 -> 0 | M15: =-M157 -> 0 | N15: =-N157 -> 0 | O15: =-O157 -> 0 | ... V15: =-V157 -> 0
C16: Initial Investment | D16: =SUM(D12:D15) -> 12480240 | E16: =+D16/$D$8 -> 196.46805 | G16: Leasing Commissions | H16: =-H158 -> -552586.68 | I16: =-I158 -> 0 | J16: =-J158 -> 0 | K16: =-K158 -> 0 | L16: =-L158 -> 0 | M16: =-M158 -> 0 | N16: =-N158 -> 0 | O16: =-O158 -> 0 | ... V16: =-V158 -> 0
C17: Capital Improvements | D17: =G74 -> 952845 | E17: =+D17/$D$8 -> 15 | G17: Capital Reserves | H17: =-H159 -> -16198.365 | I17: =-I159 -> -16684.316 | J17: =-J159 -> -17184.845 | K17: =-K159 -> -17700.391 | L17: =-L159 -> -18231.403 | M17: =-M159 -> -18778.345 | N17: =-N159 -> -19341.695 | O17: =-O159 -> -19921.946 | ... V17: =-V159 -> -8007.0198
C18: Tenant Improvements | D18: =G72 -> 327143.45 | E18: =+D18/$D$8 -> 5.15 | G18: Capital Improvements | H18: =-H160 -> -952845 | I18: =-I160 -> 0 | J18: =-J160 -> 0 | K18: =-K160 -> 0 | L18: =-L160 -> 0 | M18: =-M160 -> 0 | N18: =-N160 -> 0 | O18: =-O160 -> 0 | ... V18: =-V160 -> 0
C19: Leasing Commissions | D19: =G73 -> 552586.68 | E19: =+D19/$D$8 -> 8.6990016
C20: Total Investment | D20: =SUM(D16:D19) -> 14312815 | E20: =+D20/$D$8 -> 225.31705 | G20: Cash Flow before Debt | H20: =+SUM(H13:H18) -> -1944068.8 | I20: =+SUM(I13:I18) -> 1138807.9 | J20: =+SUM(J13:J18) -> 1184588.6 | K20: =+SUM(K13:K18) -> 1232207.3 | L20: =+SUM(L13:L18) -> 1281737.8 | M20: =+SUM(M13:M18) -> 1333256.8 | N20: =+SUM(N13:N18) -> 1386844.1 | O20: =+SUM(O13:O18) -> 1155459.8 | ... V20: =+SUM(V13:V18) -> 579802.15
C22: =UPPER("Loan Assumptions") -> LOAN ASSUMPTIONS | G22: Loan Proceeds | H22: =SUM(H160)*$E$26+SUM(H157:H158)*$E$29 -> 527838.08 | I22: =SUM(I160)*$E$26+SUM(I157:I158)*$E$29 -> 0 | J22: =SUM(J160)*$E$26+SUM(J157:J158)*$E$29 -> 0 | K22: =SUM(K160)*$E$26+SUM(K157:K158)*$E$29 -> 0 | L22: =SUM(L160)*$E$26+SUM(L157:L158)*$E$29 -> 0 | M22: =SUM(M160)*$E$26+SUM(M157:M158)*$E$29 -> 0 | N22: =SUM(N160)*$E$26+SUM(N157:N158)*$E$29 -> 0 | O22: =SUM(O160)*$E$26+SUM(O157:O158)*$E$29 -> 0 | ... V22: =SUM(V160)*$E$26+SUM(V157:V158)*$E$29 -> 0
C23: Loan to Cost - Acquisition | D23: =+D16*E23 -> 7488143.8 | E23: 0.6 | G23: Debt Service | H23: =-(H176+H204+H183) -> -590070.92 | I23: =-(I176+I204+I183) -> -590070.92 | J23: =-(J176+J204+J183) -> -590070.92 | K23: =-(K176+K204+K183) -> -590070.92 | L23: =-(L176+L204+L183) -> -590070.92 | M23: =-(M176+M204+M183) -> -590070.92 | N23: =-(N176+N204+N183) -> -590070.92 | O23: =-(O176+O204+O183) -> -590070.92 | ... V23: =-(V176+V204+V183) -> -624196.84
C24: Fixed / Avg. Floating Rate | D24: =J228 -> 0.073611808 | E24: Floating
C25: Amortization (Years) | D25: 99999 | G25: Cash Flow after Debt | H25: =SUM(H20:H23) -> -2006301.6 | I25: =SUM(I20:I23) -> 548737 | J25: =SUM(J20:J23) -> 594517.64 | K25: =SUM(K20:K23) -> 642136.36 | L25: =SUM(L20:L23) -> 691666.89 | M25: =SUM(M20:M23) -> 743185.9 | N25: =SUM(N20:N23) -> 796773.16 | O25: =SUM(O20:O23) -> 565388.88 | ... V25: =SUM(V20:V23) -> -44394.688
C26: ="CapEx Funding (Yrs 1-"&D34&")" -> CapEx Funding (Yrs 1-5) | D26: =+D17*E26 -> 0 | E26: 0
C27: Fixed / Avg. Floating Rate | D27: =J228 -> 0.073611808 | E27: Floating | G27: NOI Return (Cap Rate) | H27: =H68/H76 -> -0.0066580387 | I27: =I68/I76 -> 0.080731306 | J27: =J68/J76 -> 0.083964854 | K27: =K68/K76 -> 0.087327873 | L27: =L68/L76 -> 0.090825545 | M27: =M68/M76 -> 0.094463261 | N27: =N68/N76 -> 0.098246627 | O27: =O68/O76 -> 0.082120936 | ... V27: =V68/V76 -> 0.041068733
C28: Amortization (Years) | D28: 99999
C29: ="Leasing Funding (Yrs 1-"&D34&")" -> Leasing Funding (Yrs 1-5) | D29: =SUM(D18:D19)*E29 -> 527838.08 | E29: 0.6 | G29: UNLEV Cash on Cash (ROI) | H29: =H20/H76 -> -0.13582714 | I29: =I20/I76 -> 0.079565615 | J29: =J20/J76 -> 0.082764193 | K29: =K20/K76 -> 0.086091192 | L29: =L20/L76 -> 0.089551764 | M29: =M20/M76 -> 0.093151266 | N29: =N20/N76 -> 0.096895272 | O29: =O20/O76 -> 0.08072904 | ... V29: =V20/V76 -> 0.040509303
C30: Fixed / Avg. Floating Rate | D30: =J228 -> 0.073611808 | E30: Floating | G30: LEV Cash on Cash (ROE) | H30: =H25/H79 -> -0.35043799 | I30: =I25/I79 -> 0.095847149 | J30: =J25/J79 -> 0.10384359 | K30: =K25/K79 -> 0.11216109 | L30: =L25/L79 -> 0.12081252 | M30: =M25/M79 -> 0.12981128 | N30: =N25/N79 -> 0.13917129 | O30: =O25/O79 -> 0.09875571 | ... V30: =V25/V79 -> -0.00775436
C31: Amortization (Years) | D31: 99999
G32: DSCR (NOI) | H32: =H68/-H23 -> -0.161498 | I32: =I68/-I23 -> 1.958226 | J32: =J68/-J23 -> 2.0366593 | K32: =K68/-K23 -> 2.118233 | L32: =L68/-L23 -> 2.2030728 | M32: =M68/-M23 -> 2.2913096 | N32: =N68/-N23 -> 2.3830793 | O32: =O68/-O23 -> 1.991933 | ... V32: =V68/-V23 -> 0.94170482
C33: =UPPER("Sale Assumptions") -> SALE ASSUMPTIONS | G33: DSCR (CF) | H33: =H20/-H23 -> -3.2946358 | I33: =I20/-I23 -> 1.9299509 | J33: =J20/-J23 -> 2.0075359 | K33: =K20/-K23 -> 2.0882359 | L33: =L20/-L23 -> 2.1721759 | M33: =M20/-M23 -> 2.2594857 | N33: =N20/-N23 -> 2.3503007 | O33: =O20/-O23 -> 1.9581711 | ... V33: =V20/-V23 -> 0.9288771
C34: Hold Period | D34: 5 | E34: =INDEX(H5:V5,,MATCH(D34,H4:V4,0)) -> 48091 | G34: Debt Yield | H34: =H224 -> -0.012726154 | I34: =I224 -> 0.15430957 | J34: =J224 -> 0.16049016 | K34: =K224 -> 0.16691823 | L34: =L224 -> 0.17360367 | M34: =M224 -> 0.18055678 | N34: =N224 -> 0.1877883 | O34: =O224 -> 0.1569657 | ... V34: =V224 -> 0.078498648
C35: Exit Cap Rate | D35: 0.065
C36: Sales Price | D36: =INDEX($H$68:$V$68,,MATCH(D34+1,$H$67:$V$67,0))/D35 -> 20800541 | E36: =+D36/$D$8 -> 327.44897 | G36: =UPPER("Return Summary") -> RETURN SUMMARY | J36: EXIT CAP / HOLD PERIOD SENSITIVITY | Q36: EXIT CAP / PURCHASE PRICE SENSITIVITY | Y36: Increments:
C37: Less: Remaining Debt (Acq) | D37: =-INDEX($H$179:$V$179,,MATCH(D34,$H$151:$V$151,0)) -> -7488143.8 | E37: =+D37/$D$8 -> -117.88083 | G37: Unleveraged IRR | H37: =IRR(G60:V60) -> 0.13261212 | J37: =TEXT($H$39,"0.0%")&" / "&TEXT($H$40,"0.0x") -> 19.3% / 2.2x | K37: =L37-$Z$37 -> 0.06 | L37: =M37-$Z$37 -> 0.0625 | M37: 0.065 | N37: =M37+$Z$37 -> 0.0675 | O37: =N37+$Z$37 -> 0.07 | Q37: =TEXT($H$39,"0.0%")&" / "&TEXT($H$40,"0.0x") -> 19.3% / 2.2x | R37: =S37-$Z$37 -> 0.06 | S37: =T37-$Z$37 -> 0.0625 | T37: 0.065 | U37: =T37+$Z$37 -> 0.0675 | V37: =U37+$Z$37 -> 0.07 | Y37: Cap Rate | Z37: 0.0025
C38: Less: Remaining Debt (CapEx) | D38: =-INDEX($H$200:$V$200,,MATCH(D34,$H$151:$V$151,0)) -> 0 | E38: =+D38/$D$8 -> 0 | G38: Equity Multiple | H38: =SUMIF(G60:V60,">0",G60:V60)/-SUMIF(G60:V60,"<0",G60:V60) -> 1.7632656 | J38: 1 | K38: 87.9% / 1.9x | L38: 72.8% / 1.7x | M38: 58.8% / 1.6x | N38: 45.9% / 1.5x | O38: 33.9% / 1.3x | Q38: =Q39-$Z$39 -> 10000000 | R38: 28.9% / 3.1x | S38: 27.6% / 2.9x | T38: 26.3% / 2.8x | U38: 25.1% / 2.7x | V38: 23.9% / 2.6x | Y38: Years | Z38: 1
C39: Less: Remaining Debt (Leasing) | D39: =-INDEX($H$221:$V$221,,MATCH(D34,$H$151:$V$151,0)) -> 0 | E39: =+D39/$D$8 -> 0 | G39: Leveraged IRR | H39: =IRR(G65:V65) -> 0.19306892 | J39: =J38+$Z$38 -> 2 | K39: 40.6% / 1.8x | L39: 35.6% / 1.7x | M39: 30.9% / 1.6x | N39: 26.4% / 1.5x | O39: 22.1% / 1.4x | Q39: =Q40-$Z$39 -> 10500000 | R39: 27.1% / 2.9x | S39: 25.7% / 2.8x | T39: 24.5% / 2.6x | U39: 23.2% / 2.5x | V39: 22.0% / 2.4x | Y39: Purchase Price | Z39: 500000
C40: Less: Free Rent Credit | D40: =-SUM(H154:V154) -> 0 | E40: =+D40/$D$8 -> 0 | G40: Equity Multiple | H40: =SUMIF(G65:V65,">0",G65:V65)/-SUMIF(G65:V65,"<0",G65:V65) -> 2.1967092 | J40: =J39+$Z$38 -> 3 | K40: 29.6% / 2.0x | L40: 26.8% / 1.9x | M40: 24.1% / 1.8x | N40: 21.5% / 1.7x | O40: 19.0% / 1.6x | Q40: =Q41-$Z$39 -> 11000000 | R40: 25.3% / 2.7x | S40: 24.0% / 2.6x | T40: 22.7% / 2.5x | U40: 21.4% / 2.4x | V40: 20.2% / 2.3x
C41: 0.02 | D41: =-C41*D36 -> -416010.82 | E41: =+D41/$D$8 -> -6.5489795 | J41: =J40+$Z$38 -> 4 | K41: 24.8% / 2.2x | L41: 22.9% / 2.1x | M41: 21.1% / 2.0x | N41: 19.3% / 1.9x | O41: 17.6% / 1.8x | Q41: =Q42-$Z$39 -> 11500000 | R41: 23.7% / 2.6x | S41: 22.3% / 2.5x | T41: 21.0% / 2.3x | U41: 19.7% / 2.2x | V41: 18.5% / 2.1x
C42: Net Proceeds | D42: =SUM(D36:D41) -> 12896386 | E42: =+D42/$D$8 -> 203.01917 | G42: =UPPER("Return Split (Unleveraged)") -> RETURN SPLIT (UNLEVERAGED) | J42: =J41+$Z$38 -> 5 | K42: 22.0% / 2.4x | L42: 20.6% / 2.3x | M42: 19.3% / 2.2x | N42: 18.0% / 2.1x | O42: 16.8% / 2.0x | Q42: 12000000 | R42: 22.0% / 2.4x | S42: 20.6% / 2.3x | T42: 19.3% / 2.2x | U42: 18.0% / 2.1x | V42: 16.8% / 2.0x
G43: Cashflow | H43: =Z58/Z60 -> 0.11513662 | J43: =J42+$Z$38 -> 6 | K43: 20.3% / 2.7x | L43: 19.2% / 2.5x | M43: 18.1% / 2.4x | N43: 17.1% / 2.3x | O43: 16.2% / 2.2x | Q43: =Q42+$Z$39 -> 12500000 | R43: 20.4% / 2.3x | S43: 19.0% / 2.2x | T43: 17.7% / 2.1x | U43: 16.4% / 2.0x | V43: 15.1% / 1.9x
...

Sheet MLAs
G1: 1 | I1: 2 | J1: 3 | K1: 4 | L1: 5 | N1: 6 | O1: 7 | Q1: 8 | R1: 9 | T1: 10 | U1: 11
F3: =UPPER('Cash Flow'!D4)&" - MARKET LEASING ASSUMPTIONS" -> DISTRICT NORTH - MARKET LEASING ASSUMPTIONS
F4: Profile | G4: Rent PSF | H4: Recovery Type | I4: Retention | J4: Annual Increases | K4: Term | L4: Downtime New | M4: Downtime Blended | N4: Free Rent New | O4: Free Rent Renew | P4: Free Rent Blended | Q4: TIs PSF New | R4: TIs PSF Renew | S4: TIs Blended | T4: LCs New | U4: LCs Renew | V4: LCs Blended
F5: Single Tenant | G5: =IFERROR(INDEX($G$21:$V$70,MATCH(G$1,$A$21:$A$70,0),MATCH($F5,$G$22:$V$22,0)),"") -> 18.5 | H5: NNN | I5: =IFERROR(INDEX($G$21:$V$70,MATCH(I$1,$A$21:$A$70,0),MATCH($F5,$G$22:$V$22,0)),"") -> 0.75 | J5: 0.04 | K5: 86 | L5: =IFERROR(INDEX($G$21:$V$70,MATCH(L$1,$A$21:$A$70,0),MATCH($F5,$G$22:$V$22,0)),"") -> 9 | M5: =IFERROR(L5*(1-I5),"") -> 2.25 | N5: =IFERROR(INDEX($G$21:$V$70,MATCH(N$1,$A$21:$A$70,0),MATCH($F5,$G$22:$V$22,0)),"") -> 6 | O5: =IFERROR(INDEX($G$21:$V$70,MATCH(O$1,$A$21:$A$70,0),MATCH($F5,$G$22:$V$22,0)),"") -> 4 | P5: =IFERROR((N5*(1-$I5))+(O5*$I5),"") -> 4.5 | Q5: =IFERROR(INDEX($G$21:$V$70,MATCH(Q$1,$A$21:$A$70,0),MATCH($F5,$G$22:$V$22,0)),"") -> 5 | R5: =IFERROR(INDEX($G$21:$V$70,MATCH(R$1,$A$21:$A$70,0),MATCH($F5,$G$22:$V$22,0)),"") -> 2.5 | S5: =IFERROR((Q5*(1-$I5))+(R5*$I5),"") -> 3.125 | T5: =IFERROR(INDEX($G$21:$V$70,MATCH(T$1,$A$21:$A$70,0),MATCH($F5,$G$22:$V$22,0)),"") -> 0.06 | U5: =IFERROR(INDEX($G$21:$V$70,MATCH(U$1,$A$21:$A$70,0),MATCH($F5,$G$22:$V$22,0)),"") -> 0.04 | V5: =IFERROR((T5*(1-$I5))+(U5*$I5),"") -> 0.045
G6: =IFERROR(INDEX($G$21:$V$70,MATCH(G$1,$A$21:$A$70,0),MATCH($F6,$G$22:$V$22,0)),"") | I6: =IFERROR(INDEX($G$21:$V$70,MATCH(I$1,$A$21:$A$70,0),MATCH($F6,$G$22:$V$22,0)),"") | J6: =IFERROR(INDEX($G$21:$V$70,MATCH(J$1,$A$21:$A$70,0),MATCH($F6,$G$22:$V$22,0)),"") | K6: =IFERROR(INDEX($G$21:$V$70,MATCH(K$1,$A$21:$A$70,0),MATCH($F6,$G$22:$V$22,0)),"") | L6: =IFERROR(INDEX($G$21:$V$70,MATCH(L$1,$A$21:$A$70,0),MATCH($F6,$G$22:$V$22,0)),"") | M6: =IFERROR(L6*(1-I6),"") | N6: =IFERROR(INDEX($G$21:$V$70,MATCH(N$1,$A$21:$A$70,0),MATCH($F6,$G$22:$V$22,0)),"") | O6: =IFERROR(INDEX($G$21:$V$70,MATCH(O$1,$A$21:$A$70,0),MATCH($F6,$G$22:$V$22,0)),"") | P6: =IFERROR((N6*(1-$I6))+(O6*$I6),"") | Q6: =IFERROR(INDEX($G$21:$V$70,MATCH(Q$1,$A$21:$A$70,0),MATCH($F6,$G$22:$V$22,0)),"") | R6: =IFERROR(INDEX($G$21:$V$70,MATCH(R$1,$A$21:$A$70,0),MATCH($F6,$G$22:$V$22,0)),"") | S6: =IFERROR((Q6*(1-$I6))+(R6*$I6),"") | T6: =IFERROR(INDEX($G$21:$V$70,MATCH(T$1,$A$21:$A$70,0),MATCH($F6,$G$22:$V$22,0)),"") | U6: =IFERROR(INDEX($G$21:$V$70,MATCH(U$1,$A$21:$A$70,0),MATCH($F6,$G$22:$V$22,0)),"") | V6: =IFERROR((T6*(1-$I6))+(U6*$I6),"")
G7: =IFERROR(INDEX($G$21:$V$70,MATCH(G$1,$A$21:$A$70,0),MATCH($F7,$G$22:$V$22,0)),"") | I7: =IFERROR(INDEX($G$21:$V$70,MATCH(I$1,$A$21:$A$70,0),MATCH($F7,$G$22:$V$22,0)),"") | J7: =IFERROR(INDEX($G$21:$V$70,MATCH(J$1,$A$21:$A$70,0),MATCH($F7,$G$22:$V$22,0)),"") | K7: =IFERROR(INDEX($G$21:$V$70,MATCH(K$1,$A$21:$A$70,0),MATCH($F7,$G$22:$V$22,0)),"") | L7: =IFERROR(INDEX($G$21:$V$70,MATCH(L$1,$A$21:$A$70,0),MATCH($F7,$G$22:$V$22,0)),"") | M7: =IFERROR(L7*(1-I7),"") | N7: =IFERROR(INDEX($G$21:$V$70,MATCH(N$1,$A$21:$A$70,0),MATCH($F7,$G$22:$V$22,0)),"") | O7: =IFERROR(INDEX($G$21:$V$70,MATCH(O$1,$A$21:$A$70,0),MATCH($F7,$G$22:$V$22,0)),"") | P7: =IFERROR((N7*(1-$I7))+(O7*$I7),"") | Q7: =IFERROR(INDEX($G$21:$V$70,MATCH(Q$1,$A$21:$A$70,0),MATCH($F7,$G$22:$V$22,0)),"") | R7: =IFERROR(INDEX($G$21:$V$70,MATCH(R$1,$A$21:$A$70,0),MATCH($F7,$G$22:$V$22,0)),"") | S7: =IFERROR((Q7*(1-$I7))+(R7*$I7),"") | T7: =IFERROR(INDEX($G$21:$V$70,MATCH(T$1,$A$21:$A$70,0),MATCH($F7,$G$22:$V$22,0)),"") | U7: =IFERROR(INDEX($G$21:$V$70,MATCH(U$1,$A$21:$A$70,0),MATCH($F7,$G$22:$V$22,0)),"") | V7: =IFERROR((T7*(1-$I7))+(U7*$I7),"")
G8: =IFERROR(INDEX($G$21:$V$70,MATCH(G$1,$A$21:$A$70,0),MATCH($F8,$G$22:$V$22,0)),"") | I8: =IFERROR(INDEX($G$21:$V$70,MATCH(I$1,$A$21:$A$70,0),MATCH($F8,$G$22:$V$22,0)),"") | J8: =IFERROR(INDEX($G$21:$V$70,MATCH(J$1,$A$21:$A$70,0),MATCH($F8,$G$22:$V$22,0)),"") | K8: =IFERROR(INDEX($G$21:$V$70,MATCH(K$1,$A$21:$A$70,0),MATCH($F8,$G$22:$V$22,0)),"") | L8: =IFERROR(INDEX($G$21:$V$70,MATCH(L$1,$A$21:$A$70,0),MATCH($F8,$G$22:$V$22,0)),"") | M8: =IFERROR(L8*(1-I8),"") | N8: =IFERROR(INDEX($G$21:$V$70,MATCH(N$1,$A$21:$A$70,0),MATCH($F8,$G$22:$V$22,0)),"") | O8: =IFERROR(INDEX($G$21:$V$70,MATCH(O$1,$A$21:$A$70,0),MATCH($F8,$G$22:$V$22,0)),"") | P8: =IFERROR((N8*(1-$I8))+(O8*$I8),"") | Q8: =IFERROR(INDEX($G$21:$V$70,MATCH(Q$1,$A$21:$A$70,0),MATCH($F8,$G$22:$V$22,0)),"") | R8: =IFERROR(INDEX($G$21:$V$70,MATCH(R$1,$A$21:$A$70,0),MATCH($F8,$G$22:$V$22,0)),"") | S8: =IFERROR((Q8*(1-$I8))+(R8*$I8),"") | T8: =IFERROR(INDEX($G$21:$V$70,MATCH(T$1,$A$21:$A$70,0),MATCH($F8,$G$22:$V$22,0)),"") | U8: =IFERROR(INDEX($G$21:$V$70,MATCH(U$1,$A$21:$A$70,0),MATCH($F8,$G$22:$V$22,0)),"") | V8: =IFERROR((T8*(1-$I8))+(U8*$I8),"")
G9: =IFERROR(INDEX($G$21:$V$70,MATCH(G$1,$A$21:$A$70,0),MATCH($F9,$G$22:$V$22,0)),"") | I9: =IFERROR(INDEX($G$21:$V$70,MATCH(I$1,$A$21:$A$70,0),MATCH($F9,$G$22:$V$22,0)),"") | J9: =IFERROR(INDEX($G$21:$V$70,MATCH(J$1,$A$21:$A$70,0),MATCH($F9,$G$22:$V$22,0)),"") | K9: =IFERROR(INDEX($G$21:$V$70,MATCH(K$1,$A$21:$A$70,0),MATCH($F9,$G$22:$V$22,0)),"") | L9: =IFERROR(INDEX($G$21:$V$70,MATCH(L$1,$A$21:$A$70,0),MATCH($F9,$G$22:$V$22,0)),"") | M9: =IFERROR(L9*(1-I9),"") | N9: =IFERROR(INDEX($G$21:$V$70,MATCH(N$1,$A$21:$A$70,0),MATCH($F9,$G$22:$V$22,0)),"") | O9: =IFERROR(INDEX($G$21:$V$70,MATCH(O$1,$A$21:$A$70,0),MATCH($F9,$G$22:$V$22,0)),"") | P9: =IFERROR((N9*(1-$I9))+(O9*$I9),"") | Q9: =IFERROR(INDEX($G$21:$V$70,MATCH(Q$1,$A$21:$A$70,0),MATCH($F9,$G$22:$V$22,0)),"") | R9: =IFERROR(INDEX($G$21:$V$70,MATCH(R$1,$A$21:$A$70,0),MATCH($F9,$G$22:$V$22,0)),"") | S9: =IFERROR((Q9*(1-$I9))+(R9*$I9),"") | T9: =IFERROR(INDEX($G$21:$V$70,MATCH(T$1,$A$21:$A$70,0),MATCH($F9,$G$22:$V$22,0)),"") | U9: =IFERROR(INDEX($G$21:$V$70,MATCH(U$1,$A$21:$A$70,0),MATCH($F9,$G$22:$V$22,0)),"") | V9: =IFERROR((T9*(1-$I9))+(U9*$I9),"")
G10: =IFERROR(INDEX($G$21:$V$70,MATCH(G$1,$A$21:$A$70,0),MATCH($F10,$G$22:$V$22,0)),"") | I10: =IFERROR(INDEX($G$21:$V$70,MATCH(I$1,$A$21:$A$70,0),MATCH($F10,$G$22:$V$22,0)),"") | J10: =IFERROR(INDEX($G$21:$V$70,MATCH(J$1,$A$21:$A$70,0),MATCH($F10,$G$22:$V$22,0)),"") | K10: =IFERROR(INDEX($G$21:$V$70,MATCH(K$1,$A$21:$A$70,0),MATCH($F10,$G$22:$V$22,0)),"") | L10: =IFERROR(INDEX($G$21:$V$70,MATCH(L$1,$A$21:$A$70,0),MATCH($F10,$G$22:$V$22,0)),"") | M10: =IFERROR(L10*(1-I10),"") | N10: =IFERROR(INDEX($G$21:$V$70,MATCH(N$1,$A$21:$A$70,0),MATCH($F10,$G$22:$V$22,0)),"") | O10: =IFERROR(INDEX($G$21:$V$70,MATCH(O$1,$A$21:$A$70,0),MATCH($F10,$G$22:$V$22,0)),"") | P10: =IFERROR((N10*(1-$I10))+(O10*$I10),"") | Q10: =IFERROR(INDEX($G$21:$V$70,MATCH(Q$1,$A$21:$A$70,0),MATCH($F10,$G$22:$V$22,0)),"") | R10: =IFERROR(INDEX($G$21:$V$70,MATCH(R$1,$A$21:$A$70,0),MATCH($F10,$G$22:$V$22,0)),"") | S10: =IFERROR((Q10*(1-$I10))+(R10*$I10),"") | T10: =IFERROR(INDEX($G$21:$V$70,MATCH(T$1,$A$21:$A$70,0),MATCH($F10,$G$22:$V$22,0)),"") | U10: =IFERROR(INDEX($G$21:$V$70,MATCH(U$1,$A$21:$A$70,0),MATCH($F10,$G$22:$V$22,0)),"") | V10: =IFERROR((T10*(1-$I10))+(U10*$I10),"")
G11: =IFERROR(INDEX($G$21:$V$70,MATCH(G$1,$A$21:$A$70,0),MATCH($F11,$G$22:$V$22,0)),"") | I11: =IFERROR(INDEX($G$21:$V$70,MATCH(I$1,$A$21:$A$70,0),MATCH($F11,$G$22:$V$22,0)),"") | J11: =IFERROR(INDEX($G$21:$V$70,MATCH(J$1,$A$21:$A$70,0),MATCH($F11,$G$22:$V$22,0)),"") | K11: =IFERROR(INDEX($G$21:$V$70,MATCH(K$1,$A$21:$A$70,0),MATCH($F11,$G$22:$V$22,0)),"") | L11: =IFERROR(INDEX($G$21:$V$70,MATCH(L$1,$A$21:$A$70,0),MATCH($F11,$G$22:$V$22,0)),"") | M11: =IFERROR(L11*(1-I11),"") | N11: =IFERROR(INDEX($G$21:$V$70,MATCH(N$1,$A$21:$A$70,0),MATCH($F11,$G$22:$V$22,0)),"") | O11: =IFERROR(INDEX($G$21:$V$70,MATCH(O$1,$A$21:$A$70,0),MATCH($F11,$G$22:$V$22,0)),"") | P11: =IFERROR((N11*(1-$I11))+(O11*$I11),"") | Q11: =IFERROR(INDEX($G$21:$V$70,MATCH(Q$1,$A$21:$A$70,0),MATCH($F11,$G$22:$V$22,0)),"") | R11: =IFERROR(INDEX($G$21:$V$70,MATCH(R$1,$A$21:$A$70,0),MATCH($F11,$G$22:$V$22,0)),"") | S11: =IFERROR((Q11*(1-$I11))+(R11*$I11),"") | T11: =IFERROR(INDEX($G$21:$V$70,MATCH(T$1,$A$21:$A$70,0),MATCH($F11,$G$22:$V$22,0)),"") | U11: =IFERROR(INDEX($G$21:$V$70,MATCH(U$1,$A$21:$A$70,0),MATCH($F11,$G$22:$V$22,0)),"") | V11: =IFERROR((T11*(1-$I11))+(U11*$I11),"")
G12: =IFERROR(INDEX($G$21:$V$70,MATCH(G$1,$A$21:$A$70,0),MATCH($F12,$G$22:$V$22,0)),"") | I12: =IFERROR(INDEX($G$21:$V$70,MATCH(I$1,$A$21:$A$70,0),MATCH($F12,$G$22:$V$22,0)),"") | J12: =IFERROR(INDEX($G$21:$V$70,MATCH(J$1,$A$21:$A$70,0),MATCH($F12,$G$22:$V$22,0)),"") | K12: =IFERROR(INDEX($G$21:$V$70,MATCH(K$1,$A$21:$A$70,0),MATCH($F12,$G$22:$V$22,0)),"") | L12: =IFERROR(INDEX($G$21:$V$70,MATCH(L$1,$A$21:$A$70,0),MATCH($F12,$G$22:$V$22,0)),"") | M12: =IFERROR(L12*(1-I12),"") | N12: =IFERROR(INDEX($G$21:$V$70,MATCH(N$1,$A$21:$A$70,0),MATCH($F12,$G$22:$V$22,0)),"") | O12: =IFERROR(INDEX($G$21:$V$70,MATCH(O$1,$A$21:$A$70,0),MATCH($F12,$G$22:$V$22,0)),"") | P12: =IFERROR((N12*(1-$I12))+(O12*$I12),"") | Q12: =IFERROR(INDEX($G$21:$V$70,MATCH(Q$1,$A$21:$A$70,0),MATCH($F12,$G$22:$V$22,0)),"") | R12: =IFERROR(INDEX($G$21:$V$70,MATCH(R$1,$A$21:$A$70,0),MATCH($F12,$G$22:$V$22,0)),"") | S12: =IFERROR((Q12*(1-$I12))+(R12*$I12),"") | T12: =IFERROR(INDEX($G$21:$V$70,MATCH(T$1,$A$21:$A$70,0),MATCH($F12,$G$22:$V$22,0)),"") | U12: =IFERROR(INDEX($G$21:$V$70,MATCH(U$1,$A$21:$A$70,0),MATCH($F12,$G$22:$V$22,0)),"") | V12: =IFERROR((T12*(1-$I12))+(U12*$I12),"")
G13: =IFERROR(INDEX($G$21:$V$70,MATCH(G$1,$A$21:$A$70,0),MATCH($F13,$G$22:$V$22,0)),"") | I13: =IFERROR(INDEX($G$21:$V$70,MATCH(I$1,$A$21:$A$70,0),MATCH($F13,$G$22:$V$22,0)),"") | J13: =IFERROR(INDEX($G$21:$V$70,MATCH(J$1,$A$21:$A$70,0),MATCH($F13,$G$22:$V$22,0)),"") | K13: =IFERROR(INDEX($G$21:$V$70,MATCH(K$1,$A$21:$A$70,0),MATCH($F13,$G$22:$V$22,0)),"") | L13: =IFERROR(INDEX($G$21:$V$70,MATCH(L$1,$A$21:$A$70,0),MATCH($F13,$G$22:$V$22,0)),"") | M13: =IFERROR(L13*(1-I13),"") | N13: =IFERROR(INDEX($G$21:$V$70,MATCH(N$1,$A$21:$A$70,0),MATCH($F13,$G$22:$V$22,0)),"") | O13: =IFERROR(INDEX($G$21:$V$70,MATCH(O$1,$A$21:$A$70,0),MATCH($F13,$G$22:$V$22,0)),"") | P13: =IFERROR((N13*(1-$I13))+(O13*$I13),"") | Q13: =IFERROR(INDEX($G$21:$V$70,MATCH(Q$1,$A$21:$A$70,0),MATCH($F13,$G$22:$V$22,0)),"") | R13: =IFERROR(INDEX($G$21:$V$70,MATCH(R$1,$A$21:$A$70,0),MATCH($F13,$G$22:$V$22,0)),"") | S13: =IFERROR((Q13*(1-$I13))+(R13*$I13),"") | T13: =IFERROR(INDEX($G$21:$V$70,MATCH(T$1,$A$21:$A$70,0),MATCH($F13,$G$22:$V$22,0)),"") | U13: =IFERROR(INDEX($G$21:$V$70,MATCH(U$1,$A$21:$A$70,0),MATCH($F13,$G$22:$V$22,0)),"") | V13: =IFERROR((T13*(1-$I13))+(U13*$I13),"")
G14: =IFERROR(INDEX($G$21:$V$70,MATCH(G$1,$A$21:$A$70,0),MATCH($F14,$G$22:$V$22,0)),"") | I14: =IFERROR(INDEX($G$21:$V$70,MATCH(I$1,$A$21:$A$70,0),MATCH($F14,$G$22:$V$22,0)),"") | J14: =IFERROR(INDEX($G$21:$V$70,MATCH(J$1,$A$21:$A$70,0),MATCH($F14,$G$22:$V$22,0)),"") | K14: =IFERROR(INDEX($G$21:$V$70,MATCH(K$1,$A$21:$A$70,0),MATCH($F14,$G$22:$V$22,0)),"") | L14: =IFERROR(INDEX($G$21:$V$70,MATCH(L$1,$A$21:$A$70,0),MATCH($F14,$G$22:$V$22,0)),"") | M14: =IFERROR(L14*(1-I14),"") | N14: =IFERROR(INDEX($G$21:$V$70,MATCH(N$1,$A$21:$A$70,0),MATCH($F14,$G$22:$V$22,0)),"") | O14: =IFERROR(INDEX($G$21:$V$70,MATCH(O$1,$A$21:$A$70,0),MATCH($F14,$G$22:$V$22,0)),"") | P14: =IFERROR((N14*(1-$I14))+(O14*$I14),"") | Q14: =IFERROR(INDEX($G$21:$V$70,MATCH(Q$1,$A$21:$A$70,0),MATCH($F14,$G$22:$V$22,0)),"") | R14: =IFERROR(INDEX($G$21:$V$70,MATCH(R$1,$A$21:$A$70,0),MATCH($F14,$G$22:$V$22,0)),"") | S14: =IFERROR((Q14*(1-$I14))+(R14*$I14),"") | T14: =IFERROR(INDEX($G$21:$V$70,MATCH(T$1,$A$21:$A$70,0),MATCH($F14,$G$22:$V$22,0)),"") | U14: =IFERROR(INDEX($G$21:$V$70,MATCH(U$1,$A$21:$A$70,0),MATCH($F14,$G$22:$V$22,0)),"") | V14: =IFERROR((T14*(1-$I14))+(U14*$I14),"")
G15: =IFERROR(INDEX($G$21:$V$70,MATCH(G$1,$A$21:$A$70,0),MATCH($F15,$G$22:$V$22,0)),"") | I15: =IFERROR(INDEX($G$21:$V$70,MATCH(I$1,$A$21:$A$70,0),MATCH($F15,$G$22:$V$22,0)),"") | J15: =IFERROR(INDEX($G$21:$V$70,MATCH(J$1,$A$21:$A$70,0),MATCH($F15,$G$22:$V$22,0)),"") | K15: =IFERROR(INDEX($G$21:$V$70,MATCH(K$1,$A$21:$A$70,0),MATCH($F15,$G$22:$V$22,0)),"") | L15: =IFERROR(INDEX($G$21:$V$70,MATCH(L$1,$A$21:$A$70,0),MATCH($F15,$G$22:$V$22,0)),"") | M15: =IFERROR(L15*(1-I15),"") | N15: =IFERROR(INDEX($G$21:$V$70,MATCH(N$1,$A$21:$A$70,0),MATCH($F15,$G$22:$V$22,0)),"") | O15: =IFERROR(INDEX($G$21:$V$70,MATCH(O$1,$A$21:$A$70,0),MATCH($F15,$G$22:$V$22,0)),"") | P15: =IFERROR((N15*(1-$I15))+(O15*$I15),"") | Q15: =IFERROR(INDEX($G$21:$V$70,MATCH(Q$1,$A$21:$A$70,0),MATCH($F15,$G$22:$V$22,0)),"") | R15: =IFERROR(INDEX($G$21:$V$70,MATCH(R$1,$A$21:$A$70,0),MATCH($F15,$G$22:$V$22,0)),"") | S15: =IFERROR((Q15*(1-$I15))+(R15*$I15),"") | T15: =IFERROR(INDEX($G$21:$V$70,MATCH(T$1,$A$21:$A$70,0),MATCH($F15,$G$22:$V$22,0)),"") | U15: =IFERROR(INDEX($G$21:$V$70,MATCH(U$1,$A$21:$A$70,0),MATCH($F15,$G$22:$V$22,0)),"") | V15: =IFERROR((T15*(1-$I15))+(U15*$I15),"")
F18: Paste Below (Property Reports -> Market Leasing Summary)
F21: 46188.582
F23: Term Length (Years/Months)
A24: 2 | F24: Renewal Probability
A26: 5 | F26: Months Vacant
F27: Months Vacant (Blended)
F29: Market Base Rent (UOM)
A30: 1 | F30: Market Base Rent (New)
F31: Market Base Rent (Renewal)
F32: Market Base Rent (Blended)
F34: Market Rental Value (UOM)
F35: Market Rental Value
F36: Use Market or Prior
F37: Prior Rent
F39: Rent Increases(UOM)
A40: 3 | F40: Fixed Steps
F41: CPI Increase
A43: 6 | F43: New Free Rent (Months)
A44: 7 | F44: Renewal Free Rent (Months)
F45: Blended Free Rent (Months)
F47: Recovery Type
F48: Miscellaneous Rent
F49: Incentives
F51: Tenant Improvements (UOM)
A52: 8 | F52: Tenant Improvements (New)
A53: 9 | F53: Tenant Improvements (Renew)
...

Sheet Lease-Up
D1: Area | G1: Begin Date | H1: Base Rent/SF | J1: Term | K1: Improvements/SF
C3: =UPPER('Cash Flow'!D4)&" - LEASE-UP SUMMARY" -> DISTRICT NORTH - LEASE-UP SUMMARY
C4: Suite | D4: Square Feet | E4: % of Building | F4: Lease-Up | G4: Lease-Up (Date) | H4: Base Rent PSF (Trended) | I4: Recovery Type | J4: Escalations | K4: Term | L4: TI's PSF (Trended) | M4: Free Rent
D5: =IFERROR(INDEX($E$30:$R$60,MATCH($C5,$D$30:$D$60,0),MATCH(D$1,$E$27:$R$27,0)),"") -> 63523 | E5: =IFERROR(D5/'Cash Flow'!$D$8,"") -> 1 | F5: =IFERROR(DATEDIF('Cash Flow'!$D$5,'Lease-Up'!G5,"m")+1,"") -> 7 | G5: =IFERROR(INDEX($E$30:$R$60,MATCH($C5,$D$30:$D$60,0),MATCH(G$1,$E$27:$R$27,0)),"") -> 46447 | K5: =IFERROR(INDEX($E$30:$R$60,MATCH($C5,$D$30:$D$60,0),MATCH(J$1,$E$27:$R$27,0)),"") -> 7 Years 4 Months
D6: =IFERROR(INDEX($E$30:$R$60,MATCH($C6,$D$30:$D$60,0),MATCH(D$1,$E$27:$R$27,0)),"") | E6: =IFERROR(D6/'Cash Flow'!$D$8,"") | F6: =IFERROR(DATEDIF('Cash Flow'!$D$5,'Lease-Up'!G6,"m")+1,"") | K6: =IFERROR(INDEX($E$30:$R$60,MATCH($C6,$D$30:$D$60,0),MATCH(J$1,$E$27:$R$27,0)),"") | L6: =IFERROR(INDEX($E$30:$R$60,MATCH($C6,$D$30:$D$60,0),MATCH(K$1,$E$27:$R$27,0)),"")
D7: =IFERROR(INDEX($E$30:$R$60,MATCH($C7,$D$30:$D$60,0),MATCH(D$1,$E$27:$R$27,0)),"") | E7: =IFERROR(D7/'Cash Flow'!$D$8,"") | F7: =IFERROR(DATEDIF('Cash Flow'!$D$5,'Lease-Up'!G7,"m")+1,"")
E8: =IFERROR(D8/'Cash Flow'!$D$8,"") | F8: =IFERROR(DATEDIF('Cash Flow'!$D$5,'Lease-Up'!G8,"m")+1,"")
E9: =IFERROR(D9/'Cash Flow'!$D$8,"") | F9: =IFERROR(DATEDIF('Cash Flow'!$D$5,'Lease-Up'!G9,"m")+1,"")
E10: =IFERROR(D10/'Cash Flow'!$D$8,"") | F10: =IFERROR(DATEDIF('Cash Flow'!$D$5,'Lease-Up'!G10,"m")+1,"")
E11: =IFERROR(D11/'Cash Flow'!$D$8,"") | F11: =IFERROR(DATEDIF('Cash Flow'!$D$5,'Lease-Up'!G11,"m")+1,"")
E12: =IFERROR(D12/'Cash Flow'!$D$8,"") | F12: =IFERROR(DATEDIF('Cash Flow'!$D$5,'Lease-Up'!G12,"m")+1,"")
E13: =IFERROR(D13/'Cash Flow'!$D$8,"") | F13: =IFERROR(DATEDIF('Cash Flow'!$D$5,'Lease-Up'!G13,"m")+1,"")
E14: =IFERROR(D14/'Cash Flow'!$D$8,"") | F14: =IFERROR(DATEDIF('Cash Flow'!$D$5,'Lease-Up'!G14,"m")+1,"")
E15: =IFERROR(D15/'Cash Flow'!$D$8,"") | F15: =IFERROR(DATEDIF('Cash Flow'!$D$5,'Lease-Up'!G15,"m")+1,"")
C16: Total/Wtd. Avg. | D16: =SUM(D5:D15) -> 63523 | E16: =IFERROR(D16/'Cash Flow'!$D$8,"") -> 1 | F16: - | G16: - | H16: =SUMPRODUCT($D$5:$D$15,H5:H15)/$D$16 -> 18.5 | I16: - | J16: - | K16: - | L16: =SUMPRODUCT($D$5:$D$15,L5:L15)/$D$16 -> 5 | M16: =SUMPRODUCT($D$5:$D$15,M5:M15)/$D$16 -> 6
C20: Paste Below (Tenant Reports -> Leasing Activity), Report Options: Base Lease Periods Only
C23: All Tenants/ Base Lease Periods Only
C24: 46188.606
E26: Lease | F26: Lease | I26: Initial | J26: Initial | K26: Initial | L26: Building | M26: Tenant | N26: Tenant | O26: Leasing | P26: Leasing
C27: Tenants | D27: Suite | E27: Period | F27: Status | G27: Begin Date | H27: Term | I27: Area | J27: Base Rent | K27: Base Rent/SF | L27: Share % | M27: Improvements | N27: Improvements/SF | O27: Commissions | P27: Commissions/SF | Q27: Incentives | R27: Incentives/SF
C29: 2027 Leasing Activity

Sheet Rent Roll
D1: Suite | E1: Area | G1: Start Date | H1: End Date
C3: =UPPER('Cash Flow'!D4)&" - TENANT SUMMARY" -> DISTRICT NORTH - TENANT SUMMARY
C4: Tenant Name | D4: Suite | E4: Square Feet | F4: % of Building | G4: Commencement Date | H4: Expiration Date | I4: WALT (Months) | J4: Base Rent PSF (Mo. 1 Annualized) | K4: Recoveries PSF (Mo. 1 Annualized) | L4: Total Rent PSF (Mo. 1 Annualized) | M4: Recovery Type | N4: Notes | Q4: Market Rent PSF (Mo. 1 Annualized) | R4: MTM
C5: =IFERROR(_xlfn.XLOOKUP(A5,$B$36:$B$79,$C$36:$C$79),"") -> Speculative Tenant | D5: =IFERROR(INDEX($D$36:$W$79,MATCH($A5,$B$36:$B$79,0),MATCH(D$1,$D$35:$W$35,0)),"") -> 1 | F5: =IFERROR(E5/'Cash Flow'!$D$8,"") -> 1 | G5: =IFERROR(INDEX($D$36:$W$79,MATCH($A5,$B$36:$B$79,0),MATCH(G$1,$D$35:$W$35,0)),"") -> 46447 | I5: =IFERROR(DATEDIF('Cash Flow'!$D$5,H5,"m")/12,"") -> 7.75 | J5: =IFERROR(_xlfn.XLOOKUP(D5,'Argus (Lease Audit)'!$B$4:$B$40,'Argus (Lease Audit)'!$C$4:$C$40)*12,"") -> 0 | K5: =IFERROR(_xlfn.XLOOKUP(D5,'Argus (Lease Audit)'!F4:F40,'Argus (Lease Audit)'!G4:G40)*12,"") -> 0 | L5: =IFERROR(J5+K5,"") -> 0 | Q5: =IFERROR(_xlfn.XLOOKUP('Rent Roll'!D5,'Argus (Lease Audit)'!J4:J40,'Argus (Lease Audit)'!K4:K40)*12,"") -> 18.48 | R5: =IFERROR((Q5-J5)/J5,"")
A6: =A5+1 -> 2 | C6: =IFERROR(_xlfn.XLOOKUP(A6,$B$36:$B$79,$C$36:$C$79),"") | F6: =IFERROR(E6/'Cash Flow'!$D$8,"") | I6: =IFERROR(DATEDIF('Cash Flow'!$D$5,H6,"m")/12,"") | J6: =IFERROR(_xlfn.XLOOKUP(D6,'Argus (Lease Audit)'!$B$4:$B$40,'Argus (Lease Audit)'!$C$4:$C$40)*12,"") | K6: =IFERROR(_xlfn.XLOOKUP(D6,'Argus (Lease Audit)'!F5:F41,'Argus (Lease Audit)'!G5:G41)*12,"") | L6: =IFERROR(J6+K6,"") | Q6: =IFERROR(_xlfn.XLOOKUP('Rent Roll'!D6,'Argus (Lease Audit)'!J5:J41,'Argus (Lease Audit)'!K5:K41)*12,"") | R6: =IFERROR((Q6-J6)/J6,"")
A7: =A6+1 -> 3 | F7: =IFERROR(E7/'Cash Flow'!$D$8,"") | I7: =IFERROR(DATEDIF('Cash Flow'!$D$5,H7,"m")/12,"") | J7: =IFERROR(_xlfn.XLOOKUP(D7,'Argus (Lease Audit)'!$B$4:$B$40,'Argus (Lease Audit)'!$C$4:$C$40)*12,"") | K7: =IFERROR(_xlfn.XLOOKUP(D7,'Argus (Lease Audit)'!F6:F42,'Argus (Lease Audit)'!G6:G42)*12,"") | Q7: =IFERROR(_xlfn.XLOOKUP('Rent Roll'!D7,'Argus (Lease Audit)'!J6:J42,'Argus (Lease Audit)'!K6:K42)*12,"")
F8: =IFERROR(E8/'Cash Flow'!$D$8,"") | I8: =IFERROR(DATEDIF('Cash Flow'!$D$5,H8,"m")/12,"") | J8: =IFERROR(_xlfn.XLOOKUP(D8,'Argus (Lease Audit)'!$B$4:$B$40,'Argus (Lease Audit)'!$C$4:$C$40)*12,"") | K8: =IFERROR(_xlfn.XLOOKUP(D8,'Argus (Lease Audit)'!F7:F43,'Argus (Lease Audit)'!G7:G43)*12,"") | Q8: =IFERROR(_xlfn.XLOOKUP('Rent Roll'!D8,'Argus (Lease Audit)'!J7:J43,'Argus (Lease Audit)'!K7:K43)*12,"")
F9: =IFERROR(E9/'Cash Flow'!$D$8,"") | I9: =IFERROR(DATEDIF('Cash Flow'!$D$5,H9,"m")/12,"") | J9: =IFERROR(_xlfn.XLOOKUP(D9,'Argus (Lease Audit)'!$B$4:$B$40,'Argus (Lease Audit)'!$C$4:$C$40)*12,"") | K9: =IFERROR(_xlfn.XLOOKUP(D9,'Argus (Lease Audit)'!F8:F44,'Argus (Lease Audit)'!G8:G44)*12,"") | Q9: =IFERROR(_xlfn.XLOOKUP('Rent Roll'!D9,'Argus (Lease Audit)'!J8:J44,'Argus (Lease Audit)'!K8:K44)*12,"")
F10: =IFERROR(E10/'Cash Flow'!$D$8,"") | I10: =IFERROR(DATEDIF('Cash Flow'!$D$5,H10,"m")/12,"") | J10: =IFERROR(_xlfn.XLOOKUP(D10,'Argus (Lease Audit)'!$B$4:$B$40,'Argus (Lease Audit)'!$C$4:$C$40)*12,"") | K10: =IFERROR(_xlfn.XLOOKUP(D10,'Argus (Lease Audit)'!F9:F45,'Argus (Lease Audit)'!G9:G45)*12,"") | Q10: =IFERROR(_xlfn.XLOOKUP('Rent Roll'!D10,'Argus (Lease Audit)'!J9:J45,'Argus (Lease Audit)'!K9:K45)*12,"")
F11: =IFERROR(E11/'Cash Flow'!$D$8,"") | I11: =IFERROR(DATEDIF('Cash Flow'!$D$5,H11,"m")/12,"") | J11: =IFERROR(_xlfn.XLOOKUP(D11,'Argus (Lease Audit)'!$B$4:$B$40,'Argus (Lease Audit)'!$C$4:$C$40)*12,"") | K11: =IFERROR(_xlfn.XLOOKUP(D11,'Argus (Lease Audit)'!F10:F46,'Argus (Lease Audit)'!G10:G46)*12,"") | Q11: =IFERROR(_xlfn.XLOOKUP('Rent Roll'!D11,'Argus (Lease Audit)'!J10:J46,'Argus (Lease Audit)'!K10:K46)*12,"")
F12: =IFERROR(E12/'Cash Flow'!$D$8,"") | I12: =IFERROR(DATEDIF('Cash Flow'!$D$5,H12,"m")/12,"") | J12: =IFERROR(_xlfn.XLOOKUP(D12,'Argus (Lease Audit)'!$B$4:$B$40,'Argus (Lease Audit)'!$C$4:$C$40)*12,"") | K12: =IFERROR(_xlfn.XLOOKUP(D12,'Argus (Lease Audit)'!F11:F47,'Argus (Lease Audit)'!G11:G47)*12,"") | Q12: =IFERROR(_xlfn.XLOOKUP('Rent Roll'!D12,'Argus (Lease Audit)'!J11:J47,'Argus (Lease Audit)'!K11:K47)*12,"")
F13: =IFERROR(E13/'Cash Flow'!$D$8,"") | I13: =IFERROR(DATEDIF('Cash Flow'!$D$5,H13,"m")/12,"") | J13: =IFERROR(_xlfn.XLOOKUP(D13,'Argus (Lease Audit)'!$B$4:$B$40,'Argus (Lease Audit)'!$C$4:$C$40)*12,"") | K13: =IFERROR(_xlfn.XLOOKUP(D13,'Argus (Lease Audit)'!F12:F48,'Argus (Lease Audit)'!G12:G48)*12,"") | Q13: =IFERROR(_xlfn.XLOOKUP('Rent Roll'!D13,'Argus (Lease Audit)'!J12:J48,'Argus (Lease Audit)'!K12:K48)*12,"")
F14: =IFERROR(E14/'Cash Flow'!$D$8,"") | I14: =IFERROR(DATEDIF('Cash Flow'!$D$5,H14,"m")/12,"") | J14: =IFERROR(_xlfn.XLOOKUP(D14,'Argus (Lease Audit)'!$B$4:$B$40,'Argus (Lease Audit)'!$C$4:$C$40)*12,"") | K14: =IFERROR(_xlfn.XLOOKUP(D14,'Argus (Lease Audit)'!F13:F49,'Argus (Lease Audit)'!G13:G49)*12,"") | Q14: =IFERROR(_xlfn.XLOOKUP('Rent Roll'!D14,'Argus (Lease Audit)'!J13:J49,'Argus (Lease Audit)'!K13:K49)*12,"")
F15: =IFERROR(E15/'Cash Flow'!$D$8,"") | I15: =IFERROR(DATEDIF('Cash Flow'!$D$5,H15,"m")/12,"") | J15: =IFERROR(_xlfn.XLOOKUP(D15,'Argus (Lease Audit)'!$B$4:$B$40,'Argus (Lease Audit)'!$C$4:$C$40)*12,"") | K15: =IFERROR(_xlfn.XLOOKUP(D15,'Argus (Lease Audit)'!F14:F50,'Argus (Lease Audit)'!G14:G50)*12,"") | Q15: =IFERROR(_xlfn.XLOOKUP('Rent Roll'!D15,'Argus (Lease Audit)'!J14:J50,'Argus (Lease Audit)'!K14:K50)*12,"")
F16: =IFERROR(E16/'Cash Flow'!$D$8,"") | I16: =IFERROR(DATEDIF('Cash Flow'!$D$5,H16,"m")/12,"") | J16: =IFERROR(_xlfn.XLOOKUP(D16,'Argus (Lease Audit)'!$B$4:$B$40,'Argus (Lease Audit)'!$C$4:$C$40)*12,"") | K16: =IFERROR(_xlfn.XLOOKUP(D16,'Argus (Lease Audit)'!F15:F51,'Argus (Lease Audit)'!G15:G51)*12,"") | Q16: =IFERROR(_xlfn.XLOOKUP('Rent Roll'!D16,'Argus (Lease Audit)'!J15:J51,'Argus (Lease Audit)'!K15:K51)*12,"")
F17: =IFERROR(E17/'Cash Flow'!$D$8,"") | I17: =IFERROR(DATEDIF('Cash Flow'!$D$5,H17,"m")/12,"") | J17: =IFERROR(_xlfn.XLOOKUP(D17,'Argus (Lease Audit)'!$B$4:$B$40,'Argus (Lease Audit)'!$C$4:$C$40)*12,"") | K17: =IFERROR(_xlfn.XLOOKUP(D17,'Argus (Lease Audit)'!F16:F52,'Argus (Lease Audit)'!G16:G52)*12,"") | Q17: =IFERROR(_xlfn.XLOOKUP('Rent Roll'!D17,'Argus (Lease Audit)'!J16:J52,'Argus (Lease Audit)'!K16:K52)*12,"")
F18: =IFERROR(E18/'Cash Flow'!$D$8,"") | I18: =IFERROR(DATEDIF('Cash Flow'!$D$5,H18,"m")/12,"") | J18: =IFERROR(_xlfn.XLOOKUP(D18,'Argus (Lease Audit)'!$B$4:$B$40,'Argus (Lease Audit)'!$C$4:$C$40)*12,"") | K18: =IFERROR(_xlfn.XLOOKUP(D18,'Argus (Lease Audit)'!F17:F53,'Argus (Lease Audit)'!G17:G53)*12,"") | Q18: =IFERROR(_xlfn.XLOOKUP('Rent Roll'!D18,'Argus (Lease Audit)'!J17:J53,'Argus (Lease Audit)'!K17:K53)*12,"")
F19: =IFERROR(E19/'Cash Flow'!$D$8,"") | I19: =IFERROR(DATEDIF('Cash Flow'!$D$5,H19,"m")/12,"") | J19: =IFERROR(_xlfn.XLOOKUP(D19,'Argus (Lease Audit)'!$B$4:$B$40,'Argus (Lease Audit)'!$C$4:$C$40)*12,"") | K19: =IFERROR(_xlfn.XLOOKUP(D19,'Argus (Lease Audit)'!F18:F54,'Argus (Lease Audit)'!G18:G54)*12,"") | Q19: =IFERROR(_xlfn.XLOOKUP('Rent Roll'!D19,'Argus (Lease Audit)'!J18:J54,'Argus (Lease Audit)'!K18:K54)*12,"")
... F24: =IFERROR(E24/'Cash Flow'!$D$8,"") | I24: =IFERROR(DATEDIF('Cash Flow'!$D$5,H24,"m")/12,"") | J24: =IFERROR(_xlfn.XLOOKUP(D24,'Argus (Lease Audit)'!$B$4:$B$40,'Argus (Lease Audit)'!$C$4:$C$40)*12,"") | K24: =IFERROR(_xlfn.XLOOKUP(D24,'Argus (Lease Audit)'!F23:F59,'Argus (Lease Audit)'!G23:G59)*12,"") | Q24: =IFERROR(_xlfn.XLOOKUP('Rent Roll'!D24,'Argus (Lease Audit)'!J23:J59,'Argus (Lease Audit)'!K23:K59)*12,"")
C25: Occupied - Total / Wtd. Avg. | D25: - | E25: =SUM(E5:E24) -> 63523 | F25: =IFERROR(E25/'Cash Flow'!$D$8,"") -> 1 | G25: - | H25: - | I25: =SUMPRODUCT($E$5:$E$24,I5:I24)/$E$25 -> 7.75 | J25: =SUMPRODUCT($E$5:$E$24,J5:J24)/$E$25 -> 0 | K25: =SUMPRODUCT($E$5:$E$24,K5:K24)/$E$25 -> 0 | L25: =SUMPRODUCT($E$5:$E$24,L5:L24)/$E$25 -> 0 | M25: - | N25: - | Q25: =SUMPRODUCT($E$5:$E$24,Q5:Q24)/$E$25 -> 18.48 | R25: =SUMPRODUCT($E$5:$E$24,R5:R24)/$E$25 -> 0
C28: Paste Below (Tenant Reports -> Tenant Rent Roll), Report Options: Group By Lease Status
C31: Grouped By - Lease Status
C32: 46188.587
I34: Lease | J34: Lease | K34: Potential | L34: Absorption & | M34: Free | N34: Scheduled | O34: Miscellaneous | P34: CPI | Q34: Percentage | R34: Expense | S34: Potential | T34: Tenant | U34: Leasing | V34: Tenant | W34: Net
C35: Tenant Name | D35: Suite | E35: Lease Type | F35: Lease Status | G35: Tenant Status | H35: Area | I35: Start Date | J35: End Date | K35: Base Rent | L35: Turnover Rent | M35: Rent | N35: Base Rent | O35: Rent | P35: Increases | Q35: Rent | R35: Recoveries | S35: Gross Revenue | T35: Improvements | U35: Commissions | V35: Incentives | W35: Cash Flow
B37: =B36+IF(F37="Contract",1,0) -> 1

Sheet CapEx Detail
C3: =UPPER('Cash Flow'!D4)&" - CAPEX DETAIL" -> DISTRICT NORTH - CAPEX DETAIL
D4: ='Cash Flow'!H5 -> 46630 | E4: ='Cash Flow'!I5 -> 46996 | F4: ='Cash Flow'!J5 -> 47361 | G4: ='Cash Flow'!K5 -> 47726 | H4: ='Cash Flow'!L5 -> 48091 | I4: ='Cash Flow'!M5 -> 48457 | J4: ='Cash Flow'!N5 -> 48822 | K4: ='Cash Flow'!O5 -> 49187 | ... M4: ='Cash Flow'!Q5 -> 49918 | P4: ='Cash Flow'!D8 -> 63523
D5: 1 | E5: =+D5+1 -> 2 | F5: =+E5+1 -> 3 | G5: =+F5+1 -> 4 | H5: =+G5+1 -> 5 | I5: =+H5+1 -> 6 | J5: =+I5+1 -> 7 | K5: =+J5+1 -> 8 | L5: =+K5+1 -> 9 | M5: =+L5+1 -> 10 | N5: Total
C6: SITE IMPROVEMENTS
C7: General CAPEX PLUG | D7: 0 | E7: 0 | F7: 0 | G7: 0 | H7: 0 | I7: 0 | J7: 0 | K7: 0 | L7: 0 | M7: 0 | N7: =SUM(D7:M7) -> 0
C8: Exterior Building - Paint & Caulking | D8: 0 | E8: 0 | F8: 0 | G8: 0 | H8: 0 | I8: 0 | J8: 0 | K8: 0 | L8: 0 | M8: 0 | N8: =SUM(D8:M8) -> 0
C9: 0.03 | D9: 0 | E9: 0 | F9: 0 | G9: 0 | H9: 0 | I9: 0 | J9: 0 | K9: 0 | L9: 0 | M9: 0 | N9: =SUM(D9:M9) -> 0
C10: SUBTOTAL | D10: =SUM(D7:D9) -> 0 | E10: =SUM(E7:E9) -> 0 | F10: =SUM(F7:F9) -> 0 | G10: =SUM(G7:G9) -> 0 | H10: =SUM(H7:H9) -> 0 | I10: =SUM(I7:I9) -> 0 | J10: =SUM(J7:J9) -> 0 | K10: =SUM(K7:K9) -> 0 | ... N10: =SUM(N7:N9) -> 0
C11: PSF | D11: =+D10/$P$4 -> 0 | E11: =+E10/$P$4 -> 0 | F11: =+F10/$P$4 -> 0 | G11: =+G10/$P$4 -> 0 | H11: =+H10/$P$4 -> 0 | I11: =+I10/$P$4 -> 0 | J11: =+J10/$P$4 -> 0 | K11: =+K10/$P$4 -> 0 | ... N11: =+N10/$P$4 -> 0
C12: STRUCTURAL IMPROVEMENTS
C13: Roof Replacement | D13: 0 | E13: 0 | F13: 0 | G13: 0 | H13: 0 | I13: 0 | J13: 0 | K13: 0 | L13: 0 | M13: 0 | N13: =SUM(D13:M13) -> 0
C14: Parking Deck - Improvements & Repairs | D14: 0 | E14: 0 | F14: 0 | G14: 0 | H14: 0 | I14: 0 | J14: 0 | K14: 0 | L14: 0 | M14: 0
C15: 0.03 | D15: =+$C$15*SUM(D13:D14) -> 0 | E15: =+$C$15*SUM(E13:E14) -> 0 | F15: =+$C$15*SUM(F13:F14) -> 0 | G15: =+$C$15*SUM(G13:G14) -> 0 | H15: =+$C$15*SUM(H13:H14) -> 0 | I15: =+$C$15*SUM(I13:I14) -> 0 | J15: =+$C$15*SUM(J13:J14) -> 0 | K15: =+$C$15*SUM(K13:K14) -> 0 | ... M15: =+$C$15*SUM(M13:M14) -> 0 | N15: =SUM(D15:M15) -> 0
C16: SUBTOTAL | D16: =SUM(D13:D15) -> 0 | E16: =SUM(E13:E15) -> 0 | F16: =SUM(F13:F15) -> 0 | G16: =SUM(G13:G15) -> 0 | H16: =SUM(H13:H15) -> 0 | I16: =SUM(I13:I15) -> 0 | J16: =SUM(J13:J15) -> 0 | K16: =SUM(K13:K15) -> 0 | ... N16: =SUM(N13:N15) -> 0
C17: PSF | D17: =+D16/$P$4 -> 0 | E17: =+E16/$P$4 -> 0 | F17: =+F16/$P$4 -> 0 | G17: =+G16/$P$4 -> 0 | H17: =+H16/$P$4 -> 0 | I17: =+I16/$P$4 -> 0 | J17: =+J16/$P$4 -> 0 | K17: =+K16/$P$4 -> 0 | ... N17: =+N16/$P$4 -> 0
C18: MECHANICAL + ELECTRICAL SYSTEMS
C19: Hot Water Heater - Common Area | D19: 0 | E19: 0 | F19: 0 | G19: 0 | H19: 0 | I19: 0 | J19: 0 | K19: 0 | L19: 0 | M19: 0 | N19: =SUM(D19:M19) -> 0
C20: RTU Replacements - 4x | D20: 0 | E20: 0 | F20: 0 | G20: 0 | H20: 0 | I20: 0 | J20: 0 | K20: 0 | L20: 0 | M20: 0 | N20: =SUM(D20:M20) -> 0
C21: Split System and Air Handler - x6x | D21: 0 | E21: 0 | F21: 0 | G21: 0 | H21: 0 | I21: 0 | J21: 0 | K21: 0 | L21: 0 | M21: 0 | N21: =SUM(D21:M21) -> 0
C22: Eletric Steam Boilers - 3x | D22: 0 | E22: 0 | F22: 0 | G22: 0 | H22: 0 | I22: 0 | J22: 0 | K22: 0 | L22: 0 | M22: 0 | N22: =SUM(D22:M22) -> 0
C23: Boilers - 2x (Not due until 2037) | D23: 0 | E23: 0 | F23: 0 | G23: 0 | H23: 0 | I23: 0 | J23: 0 | K23: 0 | L23: 0 | M23: 0 | N23: =SUM(D23:M23) -> 0
C24: Emergency Generator | D24: 0 | E24: 0 | F24: 0 | G24: 0 | H24: 0 | I24: 0 | J24: 0 | K24: 0 | L24: 0 | M24: 0 | N24: =SUM(D24:M24) -> 0
C25: Transfer System for Generator | D25: 0 | E25: 0 | F25: 0 | G25: 0 | H25: 0 | I25: 0 | J25: 0 | K25: 0 | L25: 0 | M25: 0 | N25: =SUM(D25:M25) -> 0
C26: Elevator Modernization (Not due until 2044) | D26: 0 | E26: 0 | F26: 0 | G26: 0 | H26: 0 | I26: 0 | J26: 0 | K26: 0 | L26: 0 | M26: 0 | N26: =SUM(D26:M26) -> 0
C27: Main Fire Pump (Not due until 2059) | D27: 0 | E27: 0 | F27: 0 | G27: 0 | H27: 0 | I27: 0 | J27: 0 | K27: 0 | L27: 0 | M27: 0 | N27: =SUM(D27:M27) -> 0
C28: 0.03 | D28: =+$C$28*SUM(D19:D27) -> 0 | E28: =+$C$28*SUM(E19:E27) -> 0 | F28: =+$C$28*SUM(F19:F27) -> 0 | G28: =+$C$28*SUM(G19:G27) -> 0 | H28: =+$C$28*SUM(H19:H27) -> 0 | I28: =+$C$28*SUM(I19:I27) -> 0 | J28: =+$C$28*SUM(J19:J27) -> 0 | K28: =+$C$28*SUM(K19:K27) -> 0 | ... M28: =+$C$28*SUM(M19:M27) -> 0 | N28: =SUM(D28:M28) -> 0
C29: SUBTOTAL | D29: =+SUM(D19:D28) -> 0 | E29: =+SUM(E19:E28) -> 0 | F29: =+SUM(F19:F28) -> 0 | G29: =+SUM(G19:G28) -> 0 | H29: =+SUM(H19:H28) -> 0 | I29: =+SUM(I19:I28) -> 0 | J29: =+SUM(J19:J28) -> 0 | K29: =+SUM(K19:K28) -> 0 | ... N29: =+SUM(N19:N28) -> 0
C30: PSF | D30: =+D29/$P$4 -> 0 | E30: =+E29/$P$4 -> 0 | F30: =+F29/$P$4 -> 0 | G30: =+G29/$P$4 -> 0 | H30: =+H29/$P$4 -> 0 | I30: =+I29/$P$4 -> 0 | J30: =+J29/$P$4 -> 0 | K30: =+K29/$P$4 -> 0 | ... N30: =+N29/$P$4 -> 0
C31: =+UPPER("Interior Elements") -> INTERIOR ELEMENTS
C32: Office Demo | D32: 0 | E32: 0 | F32: 0 | G32: 0 | H32: 0 | I32: 0 | J32: 0 | K32: 0 | L32: 0 | M32: 0 | N32: =SUM(D32:M32) -> 0
C33: Elevator Cab Updates | D33: 0 | E33: 0 | F33: 0 | G33: 0 | H33: 0 | I33: 0 | J33: 0 | K33: 0 | L33: 0 | M33: 0 | N33: =SUM(D33:M33) -> 0
C34: 0 | D34: =+$C$34*SUM(D32:D33) -> 0 | E34: =+$C$34*SUM(E32:E33) -> 0 | F34: =+$C$34*SUM(F32:F33) -> 0 | G34: =+$C$34*SUM(G32:G33) -> 0 | H34: =+$C$34*SUM(H32:H33) -> 0 | I34: =+$C$34*SUM(I32:I33) -> 0 | J34: =+$C$34*SUM(J32:J33) -> 0 | K34: =+$C$34*SUM(K32:K33) -> 0 | ... M34: =+$C$34*SUM(M32:M33) -> 0 | N34: =SUM(D34:M34) -> 0
C35: SUBTOTAL | D35: =SUM(D32:D34) -> 0 | E35: =SUM(E32:E34) -> 0 | F35: =SUM(F32:F34) -> 0 | G35: =SUM(G32:G34) -> 0 | H35: =SUM(H32:H34) -> 0 | I35: =SUM(I32:I34) -> 0 | J35: =SUM(J32:J34) -> 0 | K35: =SUM(K32:K34) -> 0 | ... N35: =SUM(N32:N34) -> 0
C36: PSF | D36: =+D35/$P$4 -> 0 | E36: =+E35/$P$4 -> 0 | F36: =+F35/$P$4 -> 0 | G36: =+G35/$P$4 -> 0 | H36: =+H35/$P$4 -> 0 | I36: =+I35/$P$4 -> 0 | J36: =+J35/$P$4 -> 0 | K36: =+K35/$P$4 -> 0 | ... N36: =+N35/$P$4 -> 0
C37: TOTAL CAPEX BUDGET | D37: =+D35+D29+D16+D10 -> 0 | E37: =+E35+E29+E16+E10 -> 0 | F37: =+F35+F29+F16+F10 -> 0 | G37: =+G35+G29+G16+G10 -> 0 | H37: =+H35+H29+H16+H10 -> 0 | I37: =+I35+I29+I16+I10 -> 0 | J37: =+J35+J29+J16+J10 -> 0 | K37: =+K35+K29+K16+K10 -> 0 | ... N37: =+N35+N29+N16+N10 -> 0
C38: PSF | D38: =+D37/$P$4 -> 0 | E38: =+E37/$P$4 -> 0 | F38: =+F37/$P$4 -> 0 | G38: =+G37/$P$4 -> 0 | H38: =+H37/$P$4 -> 0 | I38: =+I37/$P$4 -> 0 | J38: =+J37/$P$4 -> 0 | K38: =+K37/$P$4 -> 0 | ... N38: =+N37/$P$4 -> 0
C39: 0 | D39: =+D37*$C$39 -> 0 | E39: =+E37*$C$39 -> 0 | F39: =+F37*$C$39 -> 0 | G39: =+G37*$C$39 -> 0 | H39: =+H37*$C$39 -> 0 | I39: =+I37*$C$39 -> 0 | J39: =+J37*$C$39 -> 0 | K39: =+K37*$C$39 -> 0 | ... M39: =+M37*$C$39 -> 0 | N39: =+SUM(D39:M39) -> 0
C40: TOTAL CAPEX BUDGET w/ CM | D40: =+D37+D39 -> 0 | E40: =+E37+E39 -> 0 | F40: =+F37+F39 -> 0 | G40: =+G37+G39 -> 0 | H40: =+H37+H39 -> 0 | I40: =+I37+I39 -> 0 | J40: =+J37+J39 -> 0 | K40: =+K37+K39 -> 0 | ... M40: =+M37+M39 -> 0 | N40: =+SUM(D40:M40) -> 0

Sheet Argus (Lease Audit)
A2: Paste Below (Audit Reports -> Lease Audit) -> Monthly & PSF -> Month 1 Only | E2: Paste Below (Audit Reports -> Lease Audit) -> Monthly & PSF -> Month 1 Only | I2: Paste Below (Audit Reports -> Lease Audit) -> Monthly & PSF -> Month 1 Only
A3: Scheduled Base Rent | E3: Recoveries | I3: Market Rent
